Checking for script in /app/prestart.sh

Running script /app/prestart.sh

Running inside /app/prestart.sh, you could add migrations to this file, e.g.:


#! /usr/bin/env bash


# Let the DB start



sleep 10;

# Run migrations

alembic upgrade head


[2021-04-22 04:53:06 +0000] [1] [INFO] Starting gunicorn 20.0.4

[2021-04-22 04:53:06 +0000] [1] [INFO] Listening at: http://0.0.0.0:80 (1)

[2021-04-22 04:53:06 +0000] [1] [INFO] Using worker: uvicorn.workers.UvicornWorker

[2021-04-22 04:53:06 +0000] [10] [INFO] Booting worker with pid: 10

[2021-04-22 04:53:06 +0000] [11] [INFO] Booting worker with pid: 11

[2021-04-22 04:53:06 +0000] [12] [INFO] Booting worker with pid: 12

[2021-04-22 04:53:06 +0000] [13] [INFO] Booting worker with pid: 13

[2021-04-22 04:53:18 +0000] [13] [ERROR] Exception in worker process

Traceback (most recent call last):

File "/usr/local/lib/python3.7/site-packages/gunicorn/arbiter.py", line 583, in spawn_worker

worker.init_process()

File "/usr/local/lib/python3.7/site-packages/uvicorn/workers.py", line 57, in init_process

super(UvicornWorker, self).init_process()

File "/usr/local/lib/python3.7/site-packages/gunicorn/workers/base.py", line 119, in init_process

self.load_wsgi()

File "/usr/local/lib/python3.7/site-packages/gunicorn/workers/base.py", line 144, in load_wsgi

self.wsgi = self.app.wsgi()

File "/usr/local/lib/python3.7/site-packages/gunicorn/app/base.py", line 67, in wsgi

self.callable = self.load()

File "/usr/local/lib/python3.7/site-packages/gunicorn/app/wsgiapp.py", line 49, in load

return self.load_wsgiapp()

File "/usr/local/lib/python3.7/site-packages/gunicorn/app/wsgiapp.py", line 39, in load_wsgiapp

return util.import_app(self.app_uri)

File "/usr/local/lib/python3.7/site-packages/gunicorn/util.py", line 358, in import_app

mod = importlib.import_module(module)

File "/usr/local/lib/python3.7/importlib/__init__.py", line 127, in import_module

return _bootstrap._gcd_import(name[level:], package, level)

File "<frozen importlib._bootstrap>", line 1006, in _gcd_import

File "<frozen importlib._bootstrap>", line 983, in _find_and_load

File "<frozen importlib._bootstrap>", line 967, in _find_and_load_unlocked

File "<frozen importlib._bootstrap>", line 677, in _load_unlocked

File "<frozen importlib._bootstrap_external>", line 728, in exec_module

File "<frozen importlib._bootstrap>", line 219, in _call_with_frames_removed

File "/app/main.py", line 2, in <module>

import cv2

File "/usr/local/lib/python3.7/site-packages/cv2/__init__.py", line 5, in <module>

from .cv2 import *

ImportError: libGL.so.1: cannot open shared object file: No such file or directory

[2021-04-22 04:53:18 +0000] [11] [ERROR] Exception in worker process

Traceback (most recent call last):

File "/usr/local/lib/python3.7/site-packages/gunicorn/arbiter.py", line 583, in spawn_worker

worker.init_process()

File "/usr/local/lib/python3.7/site-packages/uvicorn/workers.py", line 57, in init_process

super(UvicornWorker, self).init_process()

File "/usr/local/lib/python3.7/site-packages/gunicorn/workers/base.py", line 119, in init_process

self.load_wsgi()

File "/usr/local/lib/python3.7/site-packages/gunicorn/workers/base.py", line 144, in load_wsgi

self.wsgi = self.app.wsgi()

File "/usr/local/lib/python3.7/site-packages/gunicorn/app/base.py", line 67, in wsgi

self.callable = self.load()

File "/usr/local/lib/python3.7/site-packages/gunicorn/app/wsgiapp.py", line 49, in load

return self.load_wsgiapp()

File "/usr/local/lib/python3.7/site-packages/gunicorn/app/wsgiapp.py", line 39, in load_wsgiapp

return util.import_app(self.app_uri)

File "/usr/local/lib/python3.7/site-packages/gunicorn/util.py", line 358, in import_app

mod = importlib.import_module(module)

File "/usr/local/lib/python3.7/importlib/__init__.py", line 127, in import_module

return _bootstrap._gcd_import(name[level:], package, level)

File "<frozen importlib._bootstrap>", line 1006, in _gcd_import

File "<frozen importlib._bootstrap>", line 983, in _find_and_load

File "<frozen importlib._bootstrap>", line 967, in _find_and_load_unlocked

File "<frozen importlib._bootstrap>", line 677, in _load_unlocked

File "<frozen importlib._bootstrap_external>", line 728, in exec_module

File "<frozen importlib._bootstrap>", line 219, in _call_with_frames_removed

File "/app/main.py", line 2, in <module>

import cv2

File "/usr/local/lib/python3.7/site-packages/cv2/__init__.py", line 5, in <module>

from .cv2 import *

ImportError: libGL.so.1: cannot open shared object file: No such file or directory

[2021-04-22 04:53:18 +0000] [12] [ERROR] Exception in worker process

Traceback (most recent call last):

File "/usr/local/lib/python3.7/site-packages/gunicorn/arbiter.py", line 583, in spawn_worker

worker.init_process()

File "/usr/local/lib/python3.7/site-packages/uvicorn/workers.py", line 57, in init_process

super(UvicornWorker, self).init_process()

File "/usr/local/lib/python3.7/site-packages/gunicorn/workers/base.py", line 119, in init_process

self.load_wsgi()

File "/usr/local/lib/python3.7/site-packages/gunicorn/workers/base.py", line 144, in load_wsgi

self.wsgi = self.app.wsgi()

File "/usr/local/lib/python3.7/site-packages/gunicorn/app/base.py", line 67, in wsgi

self.callable = self.load()

File "/usr/local/lib/python3.7/site-packages/gunicorn/app/wsgiapp.py", line 49, in load

return self.load_wsgiapp()

File "/usr/local/lib/python3.7/site-packages/gunicorn/app/wsgiapp.py", line 39, in load_wsgiapp

return util.import_app(self.app_uri)

File "/usr/local/lib/python3.7/site-packages/gunicorn/util.py", line 358, in import_app

mod = importlib.import_module(module)

File "/usr/local/lib/python3.7/importlib/__init__.py", line 127, in import_module

return _bootstrap._gcd_import(name[level:], package, level)

File "<frozen importlib._bootstrap>", line 1006, in _gcd_import

File "<frozen importlib._bootstrap>", line 983, in _find_and_load

File "<frozen importlib._bootstrap>", line 967, in _find_and_load_unlocked

File "<frozen importlib._bootstrap>", line 677, in _load_unlocked

File "<frozen importlib._bootstrap_external>", line 728, in exec_module

File "<frozen importlib._bootstrap>", line 219, in _call_with_frames_removed

File "/app/main.py", line 2, in <module>

import cv2

File "/usr/local/lib/python3.7/site-packages/cv2/__init__.py", line 5, in <module>

from .cv2 import *

ImportError: libGL.so.1: cannot open shared object file: No such file or directory

[2021-04-22 04:53:18 +0000] [10] [ERROR] Exception in worker process

Traceback (most recent call last):

File "/usr/local/lib/python3.7/site-packages/gunicorn/arbiter.py", line 583, in spawn_worker

worker.init_process()

File "/usr/local/lib/python3.7/site-packages/uvicorn/workers.py", line 57, in init_process

super(UvicornWorker, self).init_process()

File "/usr/local/lib/python3.7/site-packages/gunicorn/workers/base.py", line 119, in init_process

self.load_wsgi()

File "/usr/local/lib/python3.7/site-packages/gunicorn/workers/base.py", line 144, in load_wsgi

self.wsgi = self.app.wsgi()

File "/usr/local/lib/python3.7/site-packages/gunicorn/app/base.py", line 67, in wsgi

self.callable = self.load()

File "/usr/local/lib/python3.7/site-packages/gunicorn/app/wsgiapp.py", line 49, in load

return self.load_wsgiapp()

File "/usr/local/lib/python3.7/site-packages/gunicorn/app/wsgiapp.py", line 39, in load_wsgiapp

return util.import_app(self.app_uri)

File "/usr/local/lib/python3.7/site-packages/gunicorn/util.py", line 358, in import_app

mod = importlib.import_module(module)

File "/usr/local/lib/python3.7/importlib/__init__.py", line 127, in import_module

return _bootstrap._gcd_import(name[level:], package, level)

File "<frozen importlib._bootstrap>", line 1006, in _gcd_import

File "<frozen importlib._bootstrap>", line 983, in _find_and_load

File "<frozen importlib._bootstrap>", line 967, in _find_and_load_unlocked

File "<frozen importlib._bootstrap>", line 677, in _load_unlocked

File "<frozen importlib._bootstrap_external>", line 728, in exec_module

File "<frozen importlib._bootstrap>", line 219, in _call_with_frames_removed

File "/app/main.py", line 2, in <module>

import cv2

File "/usr/local/lib/python3.7/site-packages/cv2/__init__.py", line 5, in <module>

from .cv2 import *

ImportError: libGL.so.1: cannot open shared object file: No such file or directory

[2021-04-22 04:53:18 +0000] [11] [INFO] Worker exiting (pid: 11)

[2021-04-22 04:53:18 +0000] [12] [INFO] Worker exiting (pid: 12)

[2021-04-22 04:53:18 +0000] [13] [INFO] Worker exiting (pid: 13)

{"loglevel": "info", "workers": 4, "bind": "0.0.0.0:80", "graceful_timeout": 120, "timeout": 120, "keepalive": 5, "errorlog": "-", "accesslog": "-", "workers_per_core": 1.0, "use_max_workers": null, "host": "0.0.0.0", "port": "80"}

{"loglevel": "info", "workers": 4, "bind": "0.0.0.0:80", "graceful_timeout": 120, "timeout": 120, "keepalive": 5, "errorlog": "-", "accesslog": "-", "workers_per_core": 1.0, "use_max_workers": null, "host": "0.0.0.0", "port": "80"}

{"loglevel": "info", "workers": 4, "bind": "0.0.0.0:80", "graceful_timeout": 120, "timeout": 120, "keepalive": 5, "errorlog": "-", "accesslog": "-", "workers_per_core": 1.0, "use_max_workers": null, "host": "0.0.0.0", "port": "80"}

[2021-04-22 04:53:18 +0000] [10] [INFO] Worker exiting (pid: 10)

{"loglevel": "info", "workers": 4, "bind": "0.0.0.0:80", "graceful_timeout": 120, "timeout": 120, "keepalive": 5, "errorlog": "-", "accesslog": "-", "workers_per_core": 1.0, "use_max_workers": null, "host": "0.0.0.0", "port": "80"}

{"loglevel": "info", "workers": 4, "bind": "0.0.0.0:80", "graceful_timeout": 120, "timeout": 120, "keepalive": 5, "errorlog": "-", "accesslog": "-", "workers_per_core": 1.0, "use_max_workers": null, "host": "0.0.0.0", "port": "80"}

Traceback (most recent call last):

File "/usr/local/lib/python3.7/site-packages/gunicorn/arbiter.py", line 209, in run

self.sleep()

File "/usr/local/lib/python3.7/site-packages/gunicorn/arbiter.py", line 357, in sleep

ready = select.select([self.PIPE[0]], [], [], 1.0)

File "/usr/local/lib/python3.7/site-packages/gunicorn/arbiter.py", line 242, in handle_chld

self.reap_workers()

File "/usr/local/lib/python3.7/site-packages/gunicorn/arbiter.py", line 525, in reap_workers

raise HaltServer(reason, self.WORKER_BOOT_ERROR)

gunicorn.errors.HaltServer: <HaltServer 'Worker failed to boot.' 3>


During handling of the above exception, another exception occurred:


Traceback (most recent call last):

File "/usr/local/bin/gunicorn", line 8, in <module>

sys.exit(run())

File "/usr/local/lib/python3.7/site-packages/gunicorn/app/wsgiapp.py", line 58, in run

WSGIApplication("%(prog)s [OPTIONS] [APP_MODULE]").run()

File "/usr/local/lib/python3.7/site-packages/gunicorn/app/base.py", line 228, in run

super().run()

File "/usr/local/lib/python3.7/site-packages/gunicorn/app/base.py", line 72, in run

Arbiter(self).run()

File "/usr/local/lib/python3.7/site-packages/gunicorn/arbiter.py", line 229, in run

self.halt(reason=inst.reason, exit_status=inst.exit_status)

File "/usr/local/lib/python3.7/site-packages/gunicorn/arbiter.py", line 342, in halt

self.stop()

File "/usr/local/lib/python3.7/site-packages/gunicorn/arbiter.py", line 393, in stop

time.sleep(0.1)

File "/usr/local/lib/python3.7/site-packages/gunicorn/arbiter.py", line 242, in handle_chld

self.reap_workers()

File "/usr/local/lib/python3.7/site-packages/gunicorn/arbiter.py", line 525, in reap_workers

raise HaltServer(reason, self.WORKER_BOOT_ERROR)

gunicorn.errors.HaltServer: <HaltServer 'Worker failed to boot.' 3>