2021-04-22 06:01:20.096305: W tensorflow/stream_executor/platform/default/dso_loader.cc:60] Could not load dynamic library 'libcudart.so.11.0'; dlerror: libcudart.so.11.0: cannot open shared object file: No such file or directory

2021-04-22 06:01:20.096342: I tensorflow/stream_executor/cuda/cudart_stub.cc:29] Ignore above cudart dlerror if you do not have a GPU set up on your machine.

Traceback (most recent call last):

File "/usr/local/bin/uvicorn", line 8, in <module>

sys.exit(main())

File "/usr/local/lib/python3.6/dist-packages/click/core.py", line 829, in __call__

return self.main(*args, **kwargs)

File "/usr/local/lib/python3.6/dist-packages/click/core.py", line 782, in main

rv = self.invoke(ctx)

File "/usr/local/lib/python3.6/dist-packages/click/core.py", line 1066, in invoke

return ctx.invoke(self.callback, **ctx.params)

File "/usr/local/lib/python3.6/dist-packages/click/core.py", line 610, in invoke

return callback(*args, **kwargs)

File "/usr/local/lib/python3.6/dist-packages/uvicorn/main.py", line 362, in main

run(**kwargs)

File "/usr/local/lib/python3.6/dist-packages/uvicorn/main.py", line 386, in run

server.run()

File "/usr/local/lib/python3.6/dist-packages/uvicorn/server.py", line 49, in run

loop.run_until_complete(self.serve(sockets=sockets))

File "/usr/lib/python3.6/asyncio/base_events.py", line 484, in run_until_complete

return future.result()

File "/usr/local/lib/python3.6/dist-packages/uvicorn/server.py", line 56, in serve

config.load()

File "/usr/local/lib/python3.6/dist-packages/uvicorn/config.py", line 308, in load

self.loaded_app = import_from_string(self.app)

File "/usr/local/lib/python3.6/dist-packages/uvicorn/importer.py", line 23, in import_from_string

raise exc from None

File "/usr/local/lib/python3.6/dist-packages/uvicorn/importer.py", line 20, in import_from_string

module = importlib.import_module(module_str)

File "/usr/lib/python3.6/importlib/__init__.py", line 126, in import_module

return _bootstrap._gcd_import(name[level:], package, level)

File "<frozen importlib._bootstrap>", line 994, in _gcd_import

File "<frozen importlib._bootstrap>", line 971, in _find_and_load

File "<frozen importlib._bootstrap>", line 955, in _find_and_load_unlocked

File "<frozen importlib._bootstrap>", line 665, in _load_unlocked

File "<frozen importlib._bootstrap_external>", line 678, in exec_module

File "<frozen importlib._bootstrap>", line 219, in _call_with_frames_removed

File "./app/main.py", line 3, in <module>

from keras.models import Sequential

ModuleNotFoundError: No module named 'keras'