Checking for script in /app/prestart.sh

Running script /app/prestart.sh

Running inside /app/prestart.sh, you could add migrations to this file, e.g.:


#! /usr/bin/env bash


# Let the DB start



sleep 10;

# Run migrations

alembic upgrade head


[2021-04-22 05:09:52 +0000] [1] [INFO] Starting gunicorn 20.0.4

[2021-04-22 05:09:52 +0000] [1] [INFO] Listening at: http://0.0.0.0:80 (1)

[2021-04-22 05:09:52 +0000] [1] [INFO] Using worker: uvicorn.workers.UvicornWorker

[2021-04-22 05:09:52 +0000] [9] [INFO] Booting worker with pid: 9

[2021-04-22 05:09:52 +0000] [10] [INFO] Booting worker with pid: 10

[2021-04-22 05:09:52 +0000] [17] [INFO] Booting worker with pid: 17

[2021-04-22 05:09:52 +0000] [18] [INFO] Booting worker with pid: 18

[2021-04-22 05:09:53 +0000] [9] [ERROR] Exception in worker process

Traceback (most recent call last):

File "/usr/local/lib/python3.7/site-packages/gunicorn/arbiter.py", line 583, in spawn_worker

worker.init_process()

File "/usr/local/lib/python3.7/site-packages/uvicorn/workers.py", line 57, in init_process

super(UvicornWorker, self).init_process()

File "/usr/local/lib/python3.7/site-packages/gunicorn/workers/base.py", line 119, in init_process

self.load_wsgi()

File "/usr/local/lib/python3.7/site-packages/gunicorn/workers/base.py", line 144, in load_wsgi

self.wsgi = self.app.wsgi()

File "/usr/local/lib/python3.7/site-packages/gunicorn/app/base.py", line 67, in wsgi

self.callable = self.load()

File "/usr/local/lib/python3.7/site-packages/gunicorn/app/wsgiapp.py", line 49, in load

return self.load_wsgiapp()

File "/usr/local/lib/python3.7/site-packages/gunicorn/app/wsgiapp.py", line 39, in load_wsgiapp

return util.import_app(self.app_uri)

File "/usr/local/lib/python3.7/site-packages/gunicorn/util.py", line 358, in import_app

mod = importlib.import_module(module)

File "/usr/local/lib/python3.7/importlib/__init__.py", line 127, in import_module

return _bootstrap._gcd_import(name[level:], package, level)

File "<frozen importlib._bootstrap>", line 1006, in _gcd_import

File "<frozen importlib._bootstrap>", line 983, in _find_and_load

File "<frozen importlib._bootstrap>", line 967, in _find_and_load_unlocked

File "<frozen importlib._bootstrap>", line 677, in _load_unlocked

File "<frozen importlib._bootstrap_external>", line 728, in exec_module

File "<frozen importlib._bootstrap>", line 219, in _call_with_frames_removed

File "/app/main.py", line 2, in <module>

import cv2

File "/usr/local/lib/python3.7/site-packages/cv2/__init__.py", line 5, in <module>

from .cv2 import *

ImportError: libGL.so.1: cannot open shared object file: No such file or directory

[2021-04-22 05:09:53 +0000] [10] [ERROR] Exception in worker process

Traceback (most recent call last):

File "/usr/local/lib/python3.7/site-packages/gunicorn/arbiter.py", line 583, in spawn_worker

worker.init_process()

File "/usr/local/lib/python3.7/site-packages/uvicorn/workers.py", line 57, in init_process

super(UvicornWorker, self).init_process()

File "/usr/local/lib/python3.7/site-packages/gunicorn/workers/base.py", line 119, in init_process

self.load_wsgi()

File "/usr/local/lib/python3.7/site-packages/gunicorn/workers/base.py", line 144, in load_wsgi

self.wsgi = self.app.wsgi()

File "/usr/local/lib/python3.7/site-packages/gunicorn/app/base.py", line 67, in wsgi

self.callable = self.load()

File "/usr/local/lib/python3.7/site-packages/gunicorn/app/wsgiapp.py", line 49, in load

return self.load_wsgiapp()

File "/usr/local/lib/python3.7/site-packages/gunicorn/app/wsgiapp.py", line 39, in load_wsgiapp

return util.import_app(self.app_uri)

File "/usr/local/lib/python3.7/site-packages/gunicorn/util.py", line 358, in import_app

mod = importlib.import_module(module)

File "/usr/local/lib/python3.7/importlib/__init__.py", line 127, in import_module

return _bootstrap._gcd_import(name[level:], package, level)

File "<frozen importlib._bootstrap>", line 1006, in _gcd_import

File "<frozen importlib._bootstrap>", line 983, in _find_and_load

File "<frozen importlib._bootstrap>", line 967, in _find_and_load_unlocked

File "<frozen importlib._bootstrap>", line 677, in _load_unlocked

File "<frozen importlib._bootstrap_external>", line 728, in exec_module

File "<frozen importlib._bootstrap>", line 219, in _call_with_frames_removed

File "/app/main.py", line 2, in <module>

import cv2

File "/usr/local/lib/python3.7/site-packages/cv2/__init__.py", line 5, in <module>

from .cv2 import *

ImportError: libGL.so.1: cannot open shared object file: No such file or directory

{"loglevel": "info", "workers": 4, "bind": "0.0.0.0:80", "graceful_timeout": 120, "timeout": 120, "keepalive": 5, "errorlog": "-", "accesslog": "-", "workers_per_core": 1.0, "use_max_workers": null, "host": "0.0.0.0", "port": "80"}

{"loglevel": "info", "workers": 4, "bind": "0.0.0.0:80", "graceful_timeout": 120, "timeout": 120, "keepalive": 5, "errorlog": "-", "accesslog": "-", "workers_per_core": 1.0, "use_max_workers": null, "host": "0.0.0.0", "port": "80"}

[2021-04-22 05:09:53 +0000] [10] [INFO] Worker exiting (pid: 10)

[2021-04-22 05:09:53 +0000] [9] [INFO] Worker exiting (pid: 9)

[2021-04-22 05:09:53 +0000] [17] [ERROR] Exception in worker process

Traceback (most recent call last):

File "/usr/local/lib/python3.7/site-packages/gunicorn/arbiter.py", line 583, in spawn_worker

worker.init_process()

File "/usr/local/lib/python3.7/site-packages/uvicorn/workers.py", line 57, in init_process

super(UvicornWorker, self).init_process()

File "/usr/local/lib/python3.7/site-packages/gunicorn/workers/base.py", line 119, in init_process

self.load_wsgi()

File "/usr/local/lib/python3.7/site-packages/gunicorn/workers/base.py", line 144, in load_wsgi

self.wsgi = self.app.wsgi()

File "/usr/local/lib/python3.7/site-packages/gunicorn/app/base.py", line 67, in wsgi

self.callable = self.load()

File "/usr/local/lib/python3.7/site-packages/gunicorn/app/wsgiapp.py", line 49, in load

return self.load_wsgiapp()

File "/usr/local/lib/python3.7/site-packages/gunicorn/app/wsgiapp.py", line 39, in load_wsgiapp

return util.import_app(self.app_uri)

File "/usr/local/lib/python3.7/site-packages/gunicorn/util.py", line 358, in import_app

mod = importlib.import_module(module)

File "/usr/local/lib/python3.7/importlib/__init__.py", line 127, in import_module

return _bootstrap._gcd_import(name[level:], package, level)

File "<frozen importlib._bootstrap>", line 1006, in _gcd_import

File "<frozen importlib._bootstrap>", line 983, in _find_and_load

File "<frozen importlib._bootstrap>", line 967, in _find_and_load_unlocked

File "<frozen importlib._bootstrap>", line 677, in _load_unlocked

File "<frozen importlib._bootstrap_external>", line 728, in exec_module

File "<frozen importlib._bootstrap>", line 219, in _call_with_frames_removed

File "/app/main.py", line 2, in <module>

import cv2

File "/usr/local/lib/python3.7/site-packages/cv2/__init__.py", line 5, in <module>

from .cv2 import *

ImportError: libGL.so.1: cannot open shared object file: No such file or directory

[2021-04-22 05:09:53 +0000] [17] [INFO] Worker exiting (pid: 17)

{"loglevel": "info", "workers": 4, "bind": "0.0.0.0:80", "graceful_timeout": 120, "timeout": 120, "keepalive": 5, "errorlog": "-", "accesslog": "-", "workers_per_core": 1.0, "use_max_workers": null, "host": "0.0.0.0", "port": "80"}

[2021-04-22 05:09:53 +0000] [18] [ERROR] Exception in worker process

Traceback (most recent call last):

File "/usr/local/lib/python3.7/site-packages/gunicorn/arbiter.py", line 583, in spawn_worker

worker.init_process()

File "/usr/local/lib/python3.7/site-packages/uvicorn/workers.py", line 57, in init_process

super(UvicornWorker, self).init_process()

File "/usr/local/lib/python3.7/site-packages/gunicorn/workers/base.py", line 119, in init_process

self.load_wsgi()

File "/usr/local/lib/python3.7/site-packages/gunicorn/workers/base.py", line 144, in load_wsgi

self.wsgi = self.app.wsgi()

File "/usr/local/lib/python3.7/site-packages/gunicorn/app/base.py", line 67, in wsgi

self.callable = self.load()

File "/usr/local/lib/python3.7/site-packages/gunicorn/app/wsgiapp.py", line 49, in load

return self.load_wsgiapp()

File "/usr/local/lib/python3.7/site-packages/gunicorn/app/wsgiapp.py", line 39, in load_wsgiapp

return util.import_app(self.app_uri)

File "/usr/local/lib/python3.7/site-packages/gunicorn/util.py", line 358, in import_app

mod = importlib.import_module(module)

File "/usr/local/lib/python3.7/importlib/__init__.py", line 127, in import_module

return _bootstrap._gcd_import(name[level:], package, level)

File "<frozen importlib._bootstrap>", line 1006, in _gcd_import

File "<frozen importlib._bootstrap>", line 983, in _find_and_load

File "<frozen importlib._bootstrap>", line 967, in _find_and_load_unlocked

File "<frozen importlib._bootstrap>", line 677, in _load_unlocked

File "<frozen importlib._bootstrap_external>", line 728, in exec_module

File "<frozen importlib._bootstrap>", line 219, in _call_with_frames_removed

File "/app/main.py", line 2, in <module>

import cv2

File "/usr/local/lib/python3.7/site-packages/cv2/__init__.py", line 5, in <module>

from .cv2 import *

ImportError: libGL.so.1: cannot open shared object file: No such file or directory

[2021-04-22 05:09:53 +0000] [18] [INFO] Worker exiting (pid: 18)

{"loglevel": "info", "workers": 4, "bind": "0.0.0.0:80", "graceful_timeout": 120, "timeout": 120, "keepalive": 5, "errorlog": "-", "accesslog": "-", "workers_per_core": 1.0, "use_max_workers": null, "host": "0.0.0.0", "port": "80"}

{"loglevel": "info", "workers": 4, "bind": "0.0.0.0:80", "graceful_timeout": 120, "timeout": 120, "keepalive": 5, "errorlog": "-", "accesslog": "-", "workers_per_core": 1.0, "use_max_workers": null, "host": "0.0.0.0", "port": "80"}

[2021-04-22 05:09:54 +0000] [1] [INFO] Shutting down: Master

[2021-04-22 05:09:54 +0000] [1] [INFO] Reason: Worker failed to boot.